<?xml version="1.0" encoding="UTF-8"?>
<robot generator="Robot 7.0.1 (Python 3.10.12 on linux)" generated="2024-11-25T22:48:58.080679" rpa="false" schemaversion="5">
<suite id="s1" name="Omni" source="/home/condabu/development/dashqa/testrunner/suites/Omni">
<suite id="s1-s1" name="Login" source="/home/condabu/development/dashqa/testrunner/suites/Omni/Login">
<suite id="s1-s1-s1" name="Login" source="/home/condabu/development/dashqa/testrunner/suites/Omni/Login/Login.robot">
<test id="s1-s1-s1-t1" name="Verify whether the Customer able to Login into Coop Bank application with valid Username and Password" line="8">
<kw name="Launch Application" owner="common_keywords">
<kw name="Open Browser" owner="SeleniumLibrary">
<msg time="2024-11-25T22:48:58.238281" level="INFO">Opening browser 'headlesschrome' to base url 'https://condabu.com'.</msg>
<msg time="2024-11-25T22:49:02.125828" level="WARN">Retrying (Retry(total=2, connect=None, read=None, redirect=None, status=None)) after connection broken by 'ConnectionResetError(104, 'Connection reset by peer')': /session/bf39345add701f42d18eb4a8c7a5d567/screenshot</msg>
<msg time="2024-11-25T22:49:02.129210" level="WARN">Retrying (Retry(total=1, connect=None, read=None, redirect=None, status=None)) after connection broken by 'NewConnectionError('&lt;urllib3.connection.HTTPConnection object at 0x7973a4d3d720&gt;: Failed to establish a new connection: [Errno 111] Connection refused')': /session/bf39345add701f42d18eb4a8c7a5d567/screenshot</msg>
<msg time="2024-11-25T22:49:02.132803" level="WARN">Retrying (Retry(total=0, connect=None, read=None, redirect=None, status=None)) after connection broken by 'NewConnectionError('&lt;urllib3.connection.HTTPConnection object at 0x7973a4d3d8a0&gt;: Failed to establish a new connection: [Errno 111] Connection refused')': /session/bf39345add701f42d18eb4a8c7a5d567/screenshot</msg>
<msg time="2024-11-25T22:49:02.135744" level="WARN">Keyword 'Capture Page Screenshot' could not be run on failure: HTTPConnectionPool(host='localhost', port=44939): Max retries exceeded with url: /session/bf39345add701f42d18eb4a8c7a5d567/screenshot (Caused by NewConnectionError('&lt;urllib3.connection.HTTPConnection object at 0x7973a4d3da20&gt;: Failed to establish a new connection: [Errno 111] Connection refused'))</msg>
<arg>${URL}</arg>
<arg>headlesschrome</arg>
<doc>Opens a new browser instance to the optional ``url``.</doc>
<status status="FAIL" start="2024-11-25T22:48:58.237754" elapsed="3.899171">Execution terminated by signal</status>
</kw>
<kw name="Maximize Browser Window" owner="SeleniumLibrary">
<doc>Maximizes current browser window.</doc>
<status status="NOT RUN" start="2024-11-25T22:49:02.138578" elapsed="0.000346"/>
</kw>
<kw name="Sleep" owner="BuiltIn">
<arg>30s</arg>
<doc>Pauses the test executed for the given time.</doc>
<status status="NOT RUN" start="2024-11-25T22:49:02.140099" elapsed="0.000314"/>
</kw>
<status status="FAIL" start="2024-11-25T22:48:58.235985" elapsed="3.905461">Execution terminated by signal</status>
</kw>
<kw name="Page Should Contain" owner="SeleniumLibrary">
<arg>condabu</arg>
<doc>Verifies that current page contains ``text``.</doc>
<status status="NOT RUN" start="2024-11-25T22:49:02.142726" elapsed="0.000368"/>
</kw>
<doc>This test case verifies that a user can log in with valid credentials.</doc>
<tag>Login</tag>
<tag>Smoke</tag>
<status status="FAIL" start="2024-11-25T22:48:58.224518" elapsed="3.920127">Execution terminated by signal</status>
</test>
<status status="FAIL" start="2024-11-25T22:48:58.102092" elapsed="4.097095"/>
</suite>
<status status="FAIL" start="2024-11-25T22:48:58.100816" elapsed="4.115820"/>
</suite>
<suite id="s1-s2" name="PesaLink" source="/home/condabu/development/dashqa/testrunner/suites/Omni/PesaLink">
<suite id="s1-s2-s1" name="PesalinkToMobile" source="/home/condabu/development/dashqa/testrunner/suites/Omni/PesaLink/PesalinkToMobile.robot">
<test id="s1-s2-s1-t1" name="Customer can use pesalini whether the Customer Coop Bank application with valid Username and Password" line="8">
<doc>This test case verifies that a user can log in with valid credentials.</doc>
<tag>regression</tag>
<tag>robot:exit</tag>
<status status="FAIL" start="2024-11-25T22:49:02.235787" elapsed="0.016785">Test execution stopped due to a fatal error.</status>
</test>
<status status="FAIL" start="2024-11-25T22:49:02.232712" elapsed="0.040039"/>
</suite>
<status status="FAIL" start="2024-11-25T22:49:02.226940" elapsed="0.047918"/>
</suite>
<status status="FAIL" start="2024-11-25T22:48:58.081544" elapsed="4.195270"/>
</suite>
<statistics>
<total>
<stat pass="0" fail="2" skip="0">All Tests</stat>
</total>
<tag>
<stat pass="0" fail="1" skip="0" info="combined" combined="NOT robot:exit">NOT robot:exit</stat>
<stat pass="0" fail="1" skip="0">Login</stat>
<stat pass="0" fail="1" skip="0">regression</stat>
<stat pass="0" fail="1" skip="0">Smoke</stat>
</tag>
<suite>
<stat pass="0" fail="2" skip="0" id="s1" name="Omni">Omni</stat>
<stat pass="0" fail="1" skip="0" id="s1-s1" name="Login">Omni.Login</stat>
<stat pass="0" fail="1" skip="0" id="s1-s1-s1" name="Login">Omni.Login.Login</stat>
<stat pass="0" fail="1" skip="0" id="s1-s2" name="PesaLink">Omni.PesaLink</stat>
<stat pass="0" fail="1" skip="0" id="s1-s2-s1" name="PesalinkToMobile">Omni.PesaLink.PesalinkToMobile</stat>
</suite>
</statistics>
<errors>
<msg time="2024-11-25T22:49:02.125828" level="WARN">Retrying (Retry(total=2, connect=None, read=None, redirect=None, status=None)) after connection broken by 'ConnectionResetError(104, 'Connection reset by peer')': /session/bf39345add701f42d18eb4a8c7a5d567/screenshot</msg>
<msg time="2024-11-25T22:49:02.129210" level="WARN">Retrying (Retry(total=1, connect=None, read=None, redirect=None, status=None)) after connection broken by 'NewConnectionError('&lt;urllib3.connection.HTTPConnection object at 0x7973a4d3d720&gt;: Failed to establish a new connection: [Errno 111] Connection refused')': /session/bf39345add701f42d18eb4a8c7a5d567/screenshot</msg>
<msg time="2024-11-25T22:49:02.132803" level="WARN">Retrying (Retry(total=0, connect=None, read=None, redirect=None, status=None)) after connection broken by 'NewConnectionError('&lt;urllib3.connection.HTTPConnection object at 0x7973a4d3d8a0&gt;: Failed to establish a new connection: [Errno 111] Connection refused')': /session/bf39345add701f42d18eb4a8c7a5d567/screenshot</msg>
<msg time="2024-11-25T22:49:02.135744" level="WARN">Keyword 'Capture Page Screenshot' could not be run on failure: HTTPConnectionPool(host='localhost', port=44939): Max retries exceeded with url: /session/bf39345add701f42d18eb4a8c7a5d567/screenshot (Caused by NewConnectionError('&lt;urllib3.connection.HTTPConnection object at 0x7973a4d3da20&gt;: Failed to establish a new connection: [Errno 111] Connection refused'))</msg>
</errors>
</robot>
